Workbook

Sheet yields_BRUTE
A1: Choix_Jeudi | B1: Date | C1: 42064 | D1: 42078 | E1: 42156 | F1: 42248 | G1: 42262 | H1: 42339 | I1: 42339 | J1: 42430 | K1: 42444 | L1: 42522 | M1: 42614 | N1: 42614 | O1: 42628 | P1: 42705 | Q1: 42809 | R1: 42887 | S1: 42993 | T1: 43070 | U1: 43174 | V1: 43252 | W1: 43358 | X1: 43435 | Y1: 43539 | Z1: 43617 | AA1: 43723 | AB1: 43800 | AC1: 43905 | AD1: 43983 | AE1: 43983 | AF1: 44089 | AG1: 44166 | AH1: 44270 | AI1: 44270 | AJ1: 44348 | AK1: 44348 | AL1: 44531 | AM1: 44713 | AN1: 44713 | AO1: 44896 | AP1: 45078 | AQ1: 45078 | AR1: 45261 | AS1: 45444 | AT1: 45627 | AU1: 45809 | AV1: 45809 | AW1: 47453 | AX1: 47635 | AY1: 47818 | AZ1: 48000 | BA1: 48183 | BB1: 48366 | BC1: 48549 | BD1: 48731 | BE1: 48731 | BF1: 51836 | BG1: 52018 | BH1: 52201 | BI1: 52383 | BJ1: 52566 | BK1: 52749 | BL1: 52932 | BM1: 53114 | BN1: 53297 | BO1: 53297 | BP1: 53479 | BQ1: 53662 | BR1: 53844 | BS1: 54027 | BT1: 54210 | BU1: 54393 | BV1: 54393 | BW1: 54575 | BX1: 54758 | BY1: 54940 | BZ1: 55123 | CA1: 55305 | CB1: 55488 | CC1: 55671 | CD1: 55854 | CE1: 56036 | CF1: 56219 | CG1: 56401 | CH1: 56584 | CI1: 56766 | CJ1: 56949 | CK1: 57132 | CL1: 57315 | CM1: 57497 | CN1: 57680 | CO1: 57862 | CP1: 58045 | CQ1: 58227 | CR1: 58410 | CS1: 58593 | CT1: 58776 | CU1: 58958 | CV1: 59141 | CW1: 59323 | CX1: 59506 | CY1: 59688 | CZ1: 59871 | DA1: 60054 | DB1: 60237 | DC1: 60237
A2: =WEEKDAY(B2) -> 6 | B2: 42006 | C2: 0.88329 | D2: 0.97628 | E2: 0.94752 | F2: 0.95279 | G2: 0.97214 | H2: 1.02206 | I2: 1.03671 | J2: 0.96034 | K2: 0.99392 | L2: 1.01631 | M2: 1.01343 | N2: 0.99933 | O2: 1.10608 | P2: 1.11466 | Q2: 1.04766 | R2: 1.0728 | S2: 1.15012 | T2: 1.19306 | U2: 1.2104 | V2: 1.2312 | W2: 1.28181 | X2: 1.34603 | Y2: 1.39843 | Z2: 1.34612 | AA2: 1.41706 | AB2: 1.41125 | AC2: 1.45638 | AD2: 1.41446 | AE2: 1.36108 | AF2: 1.51236 | AG2: 1.54594 | AH2: 1.60034 | AI2: 1.5843 | AJ2: 1.61886 | AK2: 1.45353 | AL2: 1.67725 | AM2: 1.73723 | AN2: 1.5939 | AO2: 1.79204 | AP2: 1.83093 | AQ2: 1.65731 | AR2: 1.88245 | AS2: 1.92497 | AT2: 1.95502 | AU2: 1.97108 | AV2: 1.88951 | AW2: 2.24468 | AX2: 2.24459 | AY2: 2.28349 | AZ2: 2.30524 | BA2: 2.32965 | BB2: 2.36229 | BC2: 2.38392 | BD2: 2.39882 | BE2: 2.28741 | BF2: 2.43362 | BG2: 2.42366 | BH2: 2.41349 | BI2: 2.40765 | BJ2: 2.40767 | BK2: 2.40502 | BL2: 2.40005 | BM2: 2.39435 | BN2: 2.39465 | BO2: 2.32379 | BP2: 2.38969 | BQ2: 2.3897 | BR2: 2.38146 | BS2: 2.38148 | BT2: 2.38149 | BW2: 2.3782 | BX2: 2.37755 | BY2: 2.37756 | BZ2: 2.37491 | CA2: 2.37493 | CB2: 2.37494 | CC2: 2.37495 | CD2: 2.37496 | CE2: 2.37164 | CF2: 2.37165 | CG2: 2.37166 | CH2: 2.37167 | CI2: 2.36535 | CJ2: 2.36503 | CK2: 2.36537 | CL2: 2.36538 | CM2: 2.36539 | CN2: 2.3654 | CO2: 2.36499 | CP2: 2.36292 | CQ2: 2.35485 | CS2: 2.35793 | CT2: 2.34737 | CU2: 2.34738 | CV2: 2.34738 | CW2: 2.35545 | CX2: 2.35546 | CY2: 2.35295 | CZ2: 2.36316 | DA2: 2.34797 | DB2: 2.34797 | DC2: 2.25287
A3: =WEEKDAY(B3) -> 2 | B3: 42009 | C3: 0.90966 | D3: 1.00072 | E3: 0.9568 | F3: 0.96171 | G3: 0.99748 | H3: 1.02519 | I3: 0.98308 | J3: 0.95205 | K3: 0.97027 | L3: 1.00383 | M3: 1.0039 | N3: 0.9847 | O3: 1.09589 | P3: 1.10389 | Q3: 1.03673 | R3: 1.05327 | S3: 1.10175 | T3: 1.1564 | U3: 1.18865 | V3: 1.20498 | W3: 1.25825 | X3: 1.32149 | Y3: 1.36238 | Z3: 1.3098 | AA3: 1.38042 | AB3: 1.37511 | AC3: 1.42586 | AD3: 1.38373 | AE3: 1.31558 | AF3: 1.46859 | AG3: 1.49935 | AH3: 1.568 | AI3: 1.54976 | AJ3: 1.57112 | AK3: 1.40588 | AL3: 1.63129 | AM3: 1.68126 | AN3: 1.54399 | AO3: 1.74112 | AP3: 1.77822 | AQ3: 1.60546 | AR3: 1.83002 | AS3: 1.87181 | AT3: 1.90444 | AU3: 1.91795 | AV3: 1.83638 | AW3: 2.19166 | AX3: 2.20079 | AY3: 2.23061 | AZ3: 2.25212 | BA3: 2.27548 | BB3: 2.3072 | BC3: 2.3288 | BD3: 2.34394 | BE3: 2.22852 | BF3: 2.38059 | BG3: 2.37061 | BH3: 2.36078 | BI3: 2.35564 | BJ3: 2.35565 | BK3: 2.35282 | BL3: 2.34784 | BM3: 2.34234 | BN3: 2.34335 | BO3: 2.27339 | BP3: 2.33838 | BQ3: 2.33839 | BR3: 2.33005 | BS3: 2.33006 | BT3: 2.33007 | BW3: 2.32677 | BX3: 2.32578 | BY3: 2.32578 | BZ3: 2.32346 | CA3: 2.32347 | CB3: 2.32348 | CC3: 2.32348 | CD3: 2.32349 | CE3: 2.32016 | CF3: 2.32017 | CG3: 2.32017 | CH3: 2.32018 | CI3: 2.31352 | CJ3: 2.31353 | CK3: 2.31353 | CL3: 2.31354 | CM3: 2.31355 | CN3: 2.31355 | CO3: 2.31356 | CP3: 2.31106 | CQ3: 2.30357 | CS3: 2.30606 | CT3: 2.29608 | CU3: 2.29609 | CV3: 2.29609 | CW3: 2.31559 | CX3: 2.3156 | CY3: 2.30107 | CZ3: 2.29809 | DA3: 2.29558 | DB3: 2.29558 | DC3: 2.20096
A4: =WEEKDAY(B4) -> 3 | B4: 42010 | C4: 0.90375 | D4: 0.96936 | E4: 0.94822 | F4: 0.96166 | G4: 0.98319 | H4: 1.00845 | I4: 0.95354 | J4: 0.93615 | K4: 0.96694 | L4: 0.98725 | M4: 0.98797 | N4: 0.95978 | O4: 1.07872 | P4: 1.08645 | Q4: 1.00981 | R4: 1.02003 | S4: 1.09487 | T4: 1.13826 | U4: 1.14955 | V4: 1.16931 | W4: 1.23528 | X4: 1.28551 | Y4: 1.31747 | Z4: 1.26271 | AA4: 1.3343 | AB4: 1.32752 | AC4: 1.36172 | AD4: 1.33542 | AE4: 1.26591 | AF4: 1.41732 | AG4: 1.44787 | AH4: 1.5002 | AI4: 1.48873 | AJ4: 1.51469 | AK4: 1.35485 | AL4: 1.57802 | AM4: 1.63524 | AN4: 1.48399 | AO4: 1.69411 | AP4: 1.72942 | AQ4: 1.55628 | AR4: 1.78159 | AS4: 1.82147 | AT4: 1.85357 | AU4: 1.86893 | AV4: 1.79433 | AW4: 2.14564 | AX4: 2.1435 | AY4: 2.1877 | AZ4: 2.21095 | BA4: 2.22842 | BB4: 2.25674 | BC4: 2.28248 | BD4: 2.29598 | BE4: 2.18672 | BF4: 2.33688 | BG4: 2.32691 | BH4: 2.31224 | BI4: 2.31197 | BJ4: 2.31198 | BK4: 2.30982 | BL4: 2.30484 | BM4: 2.29931 | BN4: 2.29933 | BO4: 2.23215 | BP4: 2.29436 | BQ4: 2.29437 | BR4: 2.28705 | BS4: 2.28706 | BT4: 2.28706 | BW4: 2.28376 | BX4: 2.28673 | BY4: 2.28674 | BZ4: 2.28045 | CA4: 2.28046 | CB4: 2.28047 | CC4: 2.2791 | CD4: 2.2791 | CE4: 2.27244 | CF4: 2.27245 | CG4: 2.27245 | CH4: 2.27717 | CI4: 2.27102 | CJ4: 2.27052 | CK4: 2.26951 | CL4: 2.26952 | CM4: 2.26952 | CN4: 2.26953 | CO4: 2.26953 | CP4: 2.26855 | CQ4: 2.26106 | CS4: 2.26356 | CT4: 2.25357 | CU4: 2.25358 | CV4: 2.25358 | CW4: 2.26107 | CX4: 2.26107 | CY4: 2.25857 | CZ4: 2.26753 | DA4: 2.25402 | DB4: 2.25403 | DC4: 2.15859
A5: =WEEKDAY(B5) -> 4 | B5: 42011 | C5: 0.87964 | D5: 0.97569 | E5: 0.94198 | F5: 0.95335 | G5: 0.97621 | H5: 0.9966 | I5: 0.95423 | J5: 0.94044 | K5: 0.96988 | L5: 0.99236 | M5: 0.99353 | N5: 0.96825 | O5: 1.08279 | P5: 1.0913 | Q5: 1.01994 | R5: 1.03015 | S5: 1.105 | T5: 1.14854 | U5: 1.15497 | V5: 1.17542 | W5: 1.24184 | X5: 1.29222 | Y5: 1.32252 | Z5: 1.26982 | AA5: 1.34118 | AB5: 1.3353 | AC5: 1.38297 | AD5: 1.34045 | AE5: 1.27619 | AF5: 1.42488 | AG5: 1.45439 | AH5: 1.50549 | AI5: 1.49401 | AJ5: 1.52624 | AK5: 1.3622 | AL5: 1.58591 | AM5: 1.63585 | AN5: 1.48891 | AO5: 1.69847 | AP5: 1.73427 | AQ5: 1.57078 | AR5: 1.78667 | AS5: 1.82944 | AT5: 1.85776 | AU5: 1.87277 | AV5: 1.7982 | AW5: 2.15157 | AX5: 2.14933 | AY5: 2.1905 | AZ5: 2.21116 | BA5: 2.23569 | BB5: 2.26517 | BC5: 2.29093 | BD5: 2.30624 | BE5: 2.19573 | BF5: 2.33689 | BG5: 2.33294 | BH5: 2.32339 | BI5: 2.32229 | BJ5: 2.32231 | BK5: 2.31298 | BL5: 2.31351 | BM5: 2.31309 | BN5: 2.31643 | BO5: 2.24109 | BP5: 2.30612 | BQ5: 2.30613 | BR5: 2.29709 | BS5: 2.29711 | BT5: 2.29712 | BW5: 2.29383 | BX5: 2.29472 | BY5: 2.29474 | BZ5: 2.29054 | CA5: 2.29055 | CB5: 2.29056 | CC5: 2.28974 | CD5: 2.28975 | CE5: 2.28476 | CF5: 2.28477 | CG5: 2.28478 | CH5: 2.28729 | CI5: 2.27981 | CJ5: 2.28065 | CK5: 2.27983 | CL5: 2.27984 | CM5: 2.27985 | CN5: 2.27985 | CO5: 2.28141 | CP5: 2.27333 | CQ5: 2.27084 | CS5: 2.26335 | CT5: 2.26336 | CU5: 2.26337 | CV5: 2.26338 | CW5: 2.28251 | CX5: 2.28252 | CY5: 2.2534 | CZ5: 2.26043 | DA5: 2.26192 | DB5: 2.26192 | DC5: 2.16815
A6: =WEEKDAY(B6) -> 5 | B6: 42012 | C6: 0.86711 | D6: 0.94053 | E6: 0.93983 | F6: 0.95326 | G6: 0.97337 | H6: 1.00518 | I6: 0.95453 | J6: 0.94437 | K6: 0.97426 | L6: 0.99784 | M6: 0.99748 | N6: 0.97614 | O6: 1.0867 | P6: 1.09598 | Q6: 1.01317 | R6: 1.04267 | S6: 1.11826 | T6: 1.16177 | U6: 1.18632 | V6: 1.20221 | W6: 1.26893 | X6: 1.32077 | Y6: 1.36192 | Z6: 1.31007 | AA6: 1.38019 | AB6: 1.37573 | AC6: 1.412 | AD6: 1.38308 | AE6: 1.31375 | AF6: 1.46678 | AG6: 1.49671 | AH6: 1.54779 | AI6: 1.53863 | AJ6: 1.56521 | AK6: 1.40405 | AL6: 1.6301 | AM6: 1.69037 | AN6: 1.54125 | AO6: 1.75304 | AP6: 1.79204 | AQ6: 1.61462 | AR6: 1.84835 | AS6: 1.88772 | AT6: 1.91589 | AU6: 1.93138 | AV6: 1.8515 | AW6: 2.21173 | AX6: 2.21053 | AY6: 2.25383 | AZ6: 2.27514 | BA6: 2.29419 | BB6: 2.32029 | BC6: 2.34605 | BD6: 2.3597 | BE6: 2.24129 | BF6: 2.40354 | BG6: 2.39358 | BH6: 2.38381 | BI6: 2.38668 | BJ6: 2.3867 | BK6: 2.38171 | BL6: 2.37674 | BM6: 2.37337 | BN6: 2.3696 | BO6: 2.29813 | BP6: 2.36463 | BQ6: 2.36465 | BR6: 2.35577 | BS6: 2.35578 | BT6: 2.35579 | BW6: 2.3525 | BX6: 2.35152 | BY6: 2.35153 | BZ6: 2.34921 | CA6: 2.34923 | CB6: 2.34924 | CC6: 2.34925 | CD6: 2.34926 | CE6: 2.34594 | CF6: 2.34595 | CG6: 2.34596 | CH6: 2.34597 | CI6: 2.33904 | CJ6: 2.33933 | CK6: 2.3399 | CL6: 2.33991 | CM6: 2.33992 | CN6: 2.33993 | CO6: 2.33994 | CP6: 2.3316 | CQ6: 2.32911 | CS6: 2.33161 | CT6: 2.32164 | CU6: 2.32165 | CV6: 2.32165 | CW6: 2.342 | CX6: 2.32914 | CY6: 2.32663 | CZ6: 2.31169 | DA6: 2.32115 | DB6: 2.32116 | DC6: 2.22683
A7: =WEEKDAY(B7) -> 6 | B7: 42013 | C7: 0.86655 | D7: 0.93518 | E7: 0.93312 | F7: 0.95317 | G7: 0.97311 | H7: 0.99936 | I7: 1.02572 | J7: 0.92853 | K7: 0.95752 | L7: 0.9801 | M7: 0.9816 | N7: 0.9483 | O7: 1.07092 | P7: 1.0808 | Q7: 0.9828 | R7: 1.01234 | S7: 1.08797 | T7: 1.13109 | U7: 1.14555 | V7: 1.16096 | W7: 1.23016 | X7: 1.27393 | Y7: 1.3181 | Z7: 1.26569 | AA7: 1.33674 | AB7: 1.33069 | AC7: 1.36706 | AD7: 1.3378 | AE7: 1.26939 | AF7: 1.42187 | AG7: 1.45218 | AH7: 1.50327 | AI7: 1.49412 | AJ7: 1.51867 | AK7: 1.35907 | AL7: 1.58303 | AM7: 1.64583 | AN7: 1.49825 | AO7: 1.70781 | AP7: 1.7483 | AQ7: 1.57568 | AR7: 1.80051 | AS7: 1.84239 | AT7: 1.87266 | AU7: 1.88586 | AV7: 1.80737 | AW7: 2.16988 | AX7: 2.16825 | AY7: 2.21197 | AZ7: 2.23292 | BA7: 2.25179 | BB7: 2.27628 | BC7: 2.30204 | BD7: 2.31708 | BE7: 2.20096 | BF7: 2.35866 | BG7: 2.3487 | BH7: 2.34338 | BI7: 2.34302 | BJ7: 2.34304 | BK7: 2.34277 | BL7: 2.33613 | BM7: 2.32948 | BN7: 2.32049 | BO7: 2.25587 | BP7: 2.3203 | BQ7: 2.32032 | BR7: 2.31188 | BS7: 2.3119 | BT7: 2.31191 | BW7: 2.30862 | BX7: 2.30763 | BY7: 2.30765 | BZ7: 2.30533 | CA7: 2.30534 | CB7: 2.30535 | CC7: 2.30536 | CD7: 2.30538 | CE7: 2.30205 | CF7: 2.30206 | CG7: 2.30207 | CH7: 2.30208 | CI7: 2.29538 | CJ7: 2.29544 | CK7: 2.29556 | CL7: 2.29557 | CM7: 2.29558 | CN7: 2.29559 | CO7: 2.2956 | CP7: 2.28794 | CQ7: 2.28545 | CS7: 2.28795 | CT7: 2.27798 | CU7: 2.27798 | CV7: 2.27799 | CW7: 2.29766 | CX7: 2.29766 | CY7: 2.28297 | CZ7: 2.28 | DA7: 2.27749 | DB7: 2.2775 | DC7: 2.18294
A8: =WEEKDAY(B8) -> 2 | B8: 42016 | C8: 0.90554 | D8: 0.97282 | E8: 0.95367 | F8: 0.96529 | G8: 0.9818 | H8: 1.0085 | I8: 0.96233 | J8: 0.92513 | K8: 0.95218 | L8: 0.97707 | M8: 0.97698 | N8: 0.93201 | O8: 1.06246 | P8: 1.07295 | Q8: 0.95454 | R8: 0.98369 | S8: 1.05873 | T8: 1.10206 | U8: 1.10873 | V8: 1.12583 | W8: 1.1939 | X8: 1.24395 | Y8: 1.27737 | Z8: 1.22369 | AA8: 1.29466 | AB8: 1.28943 | AC8: 1.32402 | AD8: 1.2959 | AE8: 1.23099 | AF8: 1.37994 | AG8: 1.41044 | AH8: 1.46179 | AI8: 1.45287 | AJ8: 1.47709 | AK8: 1.32912 | AL8: 1.5413 | AM8: 1.5977 | AN8: 1.44832 | AO8: 1.65755 | AP8: 1.69848 | AQ8: 1.5221 | AR8: 1.75493 | AS8: 1.79589 | AT8: 1.82386 | AU8: 1.83606 | AV8: 1.75677 | AW8: 2.12103 | AX8: 2.11887 | AY8: 2.15987 | AZ8: 2.1802 | BA8: 2.20239 | BB8: 2.22689 | BC8: 2.25263 | BD8: 2.26569 | BE8: 2.15072 | BF8: 2.30789 | BG8: 2.29792 | BH8: 2.29322 | BI8: 2.29229 | BJ8: 2.2923 | BK8: 2.28731 | BL8: 2.28232 | BM8: 2.27583 | BN8: 2.27524 | BO8: 2.20532 | BP8: 2.27026 | BQ8: 2.27027 | BR8: 2.26198 | BS8: 2.26199 | BT8: 2.262 | BW8: 2.25869 | BX8: 2.2577 | BY8: 2.25771 | BZ8: 2.25539 | CA8: 2.25539 | CB8: 2.2554 | CC8: 2.25541 | CD8: 2.25541 | CE8: 2.25208 | CF8: 2.25209 | CG8: 2.25209 | CH8: 2.2521 | CI8: 2.245 | CJ8: 2.24545 | CK8: 2.24595 | CL8: 2.24596 | CM8: 2.24596 | CN8: 2.24597 | CO8: 2.24543 | CP8: 2.24253 | CQ8: 2.23599 | CS8: 2.2285 | CT8: 2.2285 | CU8: 2.2285 | CV8: 2.22851 | CW8: 2.24652 | CX8: 2.24653 | CY8: 2.23254 | CZ8: 2.22518 | DA8: 2.22705 | DB8: 2.22706 | DC8: 2.13289
A9: =WEEKDAY(B9) -> 3 | B9: 42017 | C9: 0.90396 | D9: 0.9716 | E9: 0.95433 | F9: 0.96523 | G9: 0.98474 | H9: 0.99995 | I9: 0.94597 | J9: 0.92313 | K9: 0.95162 | L9: 0.97152 | M9: 0.97498 | N9: 0.92819 | O9: 1.06476 | P9: 1.05373 | Q9: 0.95657 | R9: 0.97858 | S9: 1.05414 | T9: 1.08195 | U9: 1.10042 | V9: 1.12017 | W9: 1.18589 | X9: 1.23648 | Y9: 1.25837 | Z9: 1.20434 | AA9: 1.27607 | AB9: 1.26955 | AC9: 1.30511 | AD9: 1.27683 | AE9: 1.21083 | AF9: 1.36103 | AG9: 1.39167 | AH9: 1.44345 | AI9: 1.43542 | AJ9: 1.45761 | AK9: 1.29714 | AL9: 1.52138 | AM9: 1.58453 | AN9: 1.43495 | AO9: 1.64438 | AP9: 1.68632 | AQ9: 1.51785 | AR9: 1.73886 | AS9: 1.78411 | AT9: 1.81362 | AU9: 1.82269 | AV9: 1.74196 | AW9: 2.10941 | AX9: 2.10837 | AY9: 2.14928 | AZ9: 2.16808 | BA9: 2.1875 | BB9: 2.21898 | BC9: 2.24227 | BD9: 2.25909 | BE9: 2.14308 | BF9: 2.29305 | BG9: 2.28799 | BH9: 2.27843 | BI9: 2.27698 | BJ9: 2.28061 | BK9: 2.27562 | BL9: 2.27063 | BM9: 2.26839 | BN9: 2.26385 | BO9: 2.19306 | BP9: 2.25887 | BQ9: 2.25888 | BR9: 2.25039 | BS9: 2.2504 | BT9: 2.25041 | BW9: 2.2471 | BX9: 2.24883 | BY9: 2.24884 | BZ9: 2.2438 | CA9: 2.2438 | CB9: 2.24381 | CC9: 2.24377 | CD9: 2.24377 | CE9: 2.23888 | CF9: 2.23889 | CG9: 2.23889 | CH9: 2.24051 | CI9: 2.23331 | CJ9: 2.23386 | CK9: 2.23332 | CL9: 2.23332 | CM9: 2.23333 | CN9: 2.23333 | CO9: 2.23405 | CP9: 2.22679 | CQ9: 2.22429 | CS9: 2.2168 | CT9: 2.21681 | CU9: 2.21681 | CV9: 2.21681 | CW9: 2.22335 | CX9: 2.22336 | CY9: 2.22085 | CZ9: 2.21896 | DA9: 2.21635 | DB9: 2.21636 | DC9: 2.12196
A10: =WEEKDAY(B10) -> 4 | B10: 42018 | C10: 0.88203 | D10: 0.9674 | E10: 0.93696 | F10: 0.95663 | G10: 0.97407 | H10: 0.98741 | I10: 0.9184 | J10: 0.89975 | K10: 0.93161 | L10: 0.94765 | M10: 0.95278 | N10: 0.90155 | O10: 1.04546 | P10: 1.03075 | Q10: 0.91545 | R10: 0.94779 | S10: 1.01884 | T10: 1.0476 | U10: 1.06772 | V10: 1.08948 | W10: 1.15657 | X10: 1.20731 | Y10: 1.24514 | Z10: 1.16722 | AA10: 1.24063 | AB10: 1.23021 | AC10: 1.26707 | AD10: 1.234 | AE10: 1.17362 | AF10: 1.31602 | AG10: 1.34432 | AH10: 1.41327 | AI10: 1.39512 | AJ10: 1.41676 | AK10: 1.25452 | AL10: 1.48062 | AM10: 1.54947 | AN10: 1.39799 | AO10: 1.60935 | AP10: 1.65096 | AQ10: 1.48029 | AR10: 1.70715 | AS10: 1.74705 | AT10: 1.7766 | AU10: 1.77978 | AV10: 1.69643 | AW10: 2.07868 | AX10: 2.08224 | AY10: 2.11469 | AZ10: 2.13622 | BA10: 2.15722 | BB10: 2.18672 | BC10: 2.21109 | BD10: 2.22304 | BE10: 2.10607 | BF10: 2.25862 | BG10: 2.25353 | BH10: 2.24354 | BI10: 2.24619 | BJ10: 2.24621 | BK10: 2.24122 | BL10: 2.23625 | BM10: 2.23397 | BN10: 2.22407 | BO10: 2.15878 | BP10: 2.22414 | BQ10: 2.22416 | BR10: 2.21612 | BS10: 2.21614 | BT10: 2.21615 | BW10: 2.21286 | BX10: 2.21454 | BY10: 2.21455 | BZ10: 2.20957 | CA10: 2.20958 | CB10: 2.20959 | CC10: 2.20989 | CD10: 2.2099 | CE10: 2.20462 | CF10: 2.20463 | CG10: 2.20464 | CH10: 2.20631 | CI10: 2.19953 | CJ10: 2.19967 | CK10: 2.20011 | CL10: 2.20012 | CM10: 2.20013 | CN10: 2.20013 | CO10: 2.19943 | CP10: 2.19709 | CQ10: 2.19016 | CS10: 2.1921 | CT10: 2.18268 | CU10: 2.18269 | CV10: 2.1827 | CW10: 2.18962 | CX10: 2.18963 | CY10: 2.18712 | CZ10: 2.18969 | DA10: 2.18257 | DB10: 2.18257 | DC10: 2.08779
A11: =WEEKDAY(B11) -> 5 | B11: 42019 | C11: 0.84704 | D11: 0.90747 | E11: 0.90214 | F11: 0.95654 | G11: 0.94818 | H11: 0.95399 | I11: 0.99899 | J11: 0.85231 | K11: 0.88812 | L11: 0.89688 | M11: 0.90518 | N11: 0.84206 | O11: 0.96444 | P11: 0.97841 | Q11: 0.84634 | R11: 0.87271 | S11: 0.94762 | T11: 0.99316 | U11: 0.98055 | V11: 1.0131 | W11: 1.07809 | X11: 1.11631 | Y11: 1.1236 | Z11: 1.09964 | AA11: 1.15557 | AB11: 1.14204 | AC11: 1.20112 | AD11: 1.16907 | AE11: 1.07678 | AF11: 1.24644 | AG11: 1.25807 | AH11: 1.36211 | AI11: 1.30784 | AJ11: 1.34018 | AK11: 1.1579 | AL11: 1.39826 | AM11: 1.47774 | AN11: 1.3003 | AO11: 1.53368 | AP11: 1.57275 | AQ11: 1.396 | AR11: 1.62083 | AS11: 1.65831 | AT11: 1.69039 | AU11: 1.68515 | AV11: 1.62009 | AW11: 1.98301 | AX11: 1.95856 | AY11: 2.02809 | AZ11: 2.05156 | BA11: 2.0732 | BB11: 2.10635 | BC11: 2.13917 | BD11: 2.14812 | BE11: 2.02891 | BF11: 2.18926 | BG11: 2.1793 | BH11: 2.16889 | BI11: 2.17221 | BJ11: 2.17223 | BK11: 2.16725 | BL11: 2.16227 | BM11: 2.15974 | BN11: 2.14911 | BO11: 2.08416 | BP11: 2.14868 | BQ11: 2.1487 | BR11: 2.14083 | BS11: 2.14084 | BT11: 2.14085 | BW11: 2.13756 | BX11: 2.14155 | BY11: 2.14156 | BZ11: 2.13427 | CA11: 2.13428 | CB11: 2.13429 | CC11: 2.13494 | CD11: 2.13495 | CE11: 2.12754 | CF11: 2.12755 | CG11: 2.12756 | CH11: 2.13101 | CI11: 2.12505 | CJ11: 2.12437 | CK11: 2.12506 | CL11: 2.12507 | CM11: 2.12508 | CN11: 2.12509 | CO11: 2.12396 | CP11: 2.1226 | CQ11: 2.1142 | CS11: 2.11762 | CT11: 2.10672 | CU11: 2.11763 | CV11: 2.11764 | CW11: 2.11513 | CX11: 2.11514 | CY11: 2.11263 | CZ11: 2.1225 | DA11: 2.1077 | DB11: 2.1077 | DC11: 2.01223
A12: =WEEKDAY(B12) -> 6 | B12: 42020 | C12: 0.85024 | D12: 0.92197 | E12: 0.926 | F12: 0.95644 | G12: 0.96043 | H12: 0.97832 | I12: 1.04739 | J12: 0.89377 | K12: 0.91642 | L12: 0.94296 | M12: 0.9468 | N12: 0.89281 | O12: 1.02905 | P12: 1.03791 | Q12: 0.89266 | R12: 0.92387 | S12: 1.00492 | T12: 1.04056 | U12: 1.04209 | V12: 1.05091 | W12: 1.12743 | X12: 1.15287 | Y12: 1.21026 | Z12: 1.13578 | AA12: 1.19817 | AB12: 1.19892 | AC12: 1.22634 | AD12: 1.2092 | AE12: 1.14644 | AF12: 1.27417 | AG12: 1.3036 | AH12: 1.37523 | AI12: 1.37231 | AJ12: 1.38794 | AK12: 1.22847 | AL12: 1.43989 | AM12: 1.50695 | AN12: 1.36339 | AO12: 1.57122 | AP12: 1.61369 | AQ12: 1.43545 | AR12: 1.66589 | AS12: 1.70368 | AT12: 1.73885 | AU12: 1.72031 | AV12: 1.66795 | AW12: 2.03253 | AX12: 2.01455 | AY12: 2.07719 | AZ12: 2.10858 | BA12: 2.12518 | BB12: 2.1522 | BC12: 2.17455 | BD12: 2.18692 | BE12: 2.06896 | BF12: 2.22433 | BG12: 2.22038 | BH12: 2.21073 | BI12: 2.20884 | BJ12: 2.21242 | BK12: 2.20743 | BL12: 2.20246 | BM12: 2.20083 | BN12: 2.19589 | BO12: 2.12531 | BP12: 2.19092 | BQ12: 2.19094 | BR12: 2.18265 | BS12: 2.18266 | BT12: 2.18268 | BW12: 2.17938 | BX12: 2.17939 | BY12: 2.1794 | BZ12: 2.17609 | CA12: 2.1761 | CB12: 2.17611 | CC12: 2.1766 | CD12: 2.17661 | CE12: 2.17367 | CF12: 2.17368 | CG12: 2.17369 | CH12: 2.17283 | CI12: 2.16574 | CJ12: 2.16619 | CK12: 2.16668 | CL12: 2.16669 | CM12: 2.1667 | CN12: 2.16671 | CO12: 2.1662 | CP12: 2.1633 | CQ12: 2.15674 | CS12: 2.14925 | CT12: 2.14926 | CU12: 2.14927 | CV12: 2.14927 | CW12: 2.16813 | CX12: 2.15584 | CY12: 2.15333 | CZ12: 2.15115 | DA12: 2.14864 | DB12: 2.14864 | DC12: 2.05655
A13: =WEEKDAY(B13) -> 2 | B13: 42023 | C13: 0.89346 | D13: 0.9546 | E13: 0.93067 | F13: 0.96588 | G13: 0.97017 | H13: 0.98215 | I13: 0.98352 | J13: 0.89523 | K13: 0.92251 | L13: 0.93656 | M13: 0.94707 | N13: 0.88535 | O13: 1.03552 | P13: 1.02012 | Q13: 0.89854 | R13: 0.92054 | S13: 1.02095 | T13: 1.03259 | U13: 1.02575 | V13: 1.04418 | W13: 1.1111 | X13: 1.16167 | Y13: 1.17698 | Z13: 1.12365 | AA13: 1.19389 | AB13: 1.19023 | AC13: 1.24083 | AD13: 1.19986 | AE13: 1.13405 | AF13: 1.28298 | AG13: 1.31385 | AH13: 1.35714 | AI13: 1.3454 | AJ13: 1.3779 | AK13: 1.23736 | AL13: 1.43707 | AM13: 1.49338 | AN13: 1.33972 | AO13: 1.55322 | AP13: 1.59506 | AQ13: 1.42281 | AR13: 1.64743 | AS13: 1.68853 | AT13: 1.71812 | AU13: 1.73209 | AV13: 1.6554 | AW13: 2.02638 | AX13: 2.02235 | AY13: 2.06219 | AZ13: 2.08633 | BA13: 2.10265 | BB13: 2.1297 | BC13: 2.15544 | BD13: 2.17035 | BE13: 2.0479 | BF13: 2.20603 | BG13: 2.20095 | BH13: 2.19143 | BI13: 2.19034 | BJ13: 2.19408 | BK13: 2.18909 | BL13: 2.18411 | BM13: 2.18135 | BN13: 2.17738 | BO13: 2.10675 | BP13: 2.1724 | BQ13: 2.17241 | BR13: 2.16409 | BS13: 2.16409 | BT13: 2.1641 | BW13: 2.1608 | BX13: 2.16208 | BY13: 2.16209 | BZ13: 2.15749 | CA13: 2.1575 | CB13: 2.1575 | CC13: 2.15724 | CD13: 2.15724 | CE13: 2.15213 | CF13: 2.15213 | CG13: 2.15214 | CH13: 2.1542 | CI13: 2.14727 | CJ13: 2.14755 | CK13: 2.14784 | CL13: 2.14784 | CM13: 2.14785 | CN13: 2.14785 | CO13: 2.14757 | CP13: 2.14481 | CQ13: 2.13787 | CS13: 2.13038 | CT13: 2.13038 | CU13: 2.13038 | CV13: 2.13039 | CW13: 2.14855 | CX13: 2.14856 | CY13: 2.14856 | CZ13: 2.13133 | DA13: 2.12883 | DB13: 2.12883 | DC13: 2.03698
... A41: =WEEKDAY(B41) -> 6 | B41: 42062 | C41: 0.29449 | D41: 0.48069 | E41: 0.57015 | F41: 0.59736 | G41: 0.59478 | H41: 0.61229 | I41: 0.50376 | J41: 0.49805 | K41: 0.53885 | L41: 0.54552 | M41: 0.54991 | N41: 0.47929 | O41: 0.65386 | P41: 0.62252 | Q41: 0.52414 | R41: 0.53431 | S41: 0.58315 | T41: 0.64672 | U41: 0.60614 | V41: 0.59616 | W41: 0.66822 | X41: 0.71032 | Y41: 0.7373 | Z41: 0.68465 | AA41: 0.7556 | AB41: 0.75562 | AC41: 0.8284 | AD41: 0.8008 | AE41: 0.74208 | AF41: 0.88748 | AG41: 0.92366 | AH41: 0.98204 | AI41: 0.94119 | AJ41: 0.96892 | AK41: 0.82141 | AL41: 1.05497 | AM41: 1.134 | AN41: 0.95335 | AO41: 1.17831 | AP41: 1.25333 | AQ41: 1.08391 | AR41: 1.30503 | AS41: 1.3602 | AT41: 1.39064 | AU41: 1.3896 | AV41: 1.32791 | AW41: 1.78286 | AX41: 1.79879 | AY41: 1.83031 | AZ41: 1.84226 | BA41: 1.85846 | BB41: 1.93018 | BC41: 1.9611 | BD41: 1.9991 | BE41: 1.89222 | BF41: 2.05596 | BG41: 2.05098 | BH41: 2.05042 | BI41: 2.04102 | BJ41: 2.04104 | BK41: 2.03605 | BL41: 2.03108 | BM41: 2.03083 | BN41: 2.00524 | BO41: 1.98322 | BP41: 2.0112 | BQ41: 2.01122 | BR41: 1.99878 | BS41: 1.99879 | BT41: 1.9988 | BW41: 2.00971 | BX41: 2.0133 | BY41: 2.0013 | BZ41: 1.998 | CA41: 1.99801 | CB41: 1.99802 | CC41: 1.99803 | CD41: 1.99804 | CE41: 1.99472 | CF41: 1.99473 | CG41: 1.99474 | CH41: 1.99395 | CI41: 1.99385 | CJ41: 1.98618 | CK41: 1.98397 | CL41: 1.98398 | CM41: 1.98399 | CN41: 1.984 | CO41: 1.9815 | CP41: 1.97651 | CQ41: 1.98147 | CS41: 1.98237 | CT41: 1.98051 | CU41: 1.98051 | CV41: 1.98052 | CW41: 1.97304 | CX41: 1.97305 | CY41: 1.97054 | CZ41: 1.96557 | DA41: 1.96307 | DB41: 1.96307 | DC41: 1.876
A42: =WEEKDAY(B42) -> 2 | B42: 42065 | D42: 0.55281 | E42: 0.57501 | F42: 0.60385 | G42: 0.60188 | H42: 0.61105 | I42: 0.52932 | J42: 0.52587 | K42: 0.55081 | L42: 0.56274 | M42: 0.5778 | N42: 0.5062 | O42: 0.66003 | P42: 0.63233 | Q42: 0.54134 | R42: 0.56498 | S42: 0.62979 | T42: 0.6705 | U42: 0.6297 | V42: 0.61947 | W42: 0.6933 | X42: 0.72734 | Y42: 0.79797 | Z42: 0.7454 | AA42: 0.81589 | AB42: 0.81158 | AC42: 0.88869 | AD42: 0.89415 | AE42: 0.80328 | AF42: 0.94695 | AG42: 0.98935 | AH42: 1.04388 | AI42: 1.04105 | AJ42: 1.03744 | AK42: 0.89989 | AL42: 1.11182 | AM42: 1.21331 | AN42: 1.03311 | AO42: 1.26276 | AP42: 1.33962 | AQ42: 1.16943 | AR42: 1.39132 | AS42: 1.4444 | AT42: 1.47701 | AU42: 1.47466 | AV42: 1.40843 | AW42: 1.86137 | AX42: 1.87825 | AY42: 1.90541 | AZ42: 1.92099 | BA42: 1.93794 | BB42: 2.0105 | BC42: 2.03991 | BD42: 2.06645 | BE42: 1.96872 | BF42: 2.12157 | BG42: 2.11658 | BH42: 2.11656 | BI42: 2.10661 | BJ42: 2.10662 | BK42: 2.10162 | BL42: 2.09664 | BM42: 2.09164 | BN42: 2.07257 | BO42: 2.04935 | BP42: 2.07667 | BQ42: 2.07668 | BR42: 2.06559 | BS42: 2.0656 | BT42: 2.06561 | BW42: 2.07472 | BX42: 2.07473 | BY42: 2.06673 | BZ42: 2.06342 | CA42: 2.06343 | CB42: 2.06343 | CC42: 2.06344 | CD42: 2.06344 | CE42: 2.06012 | CF42: 2.06013 | CG42: 2.06013 | CH42: 2.06014 | CI42: 2.05919 | CJ42: 2.05304 | CK42: 2.05071 | CL42: 2.05072 | CM42: 2.05072 | CN42: 2.05073 | CO42: 2.04823 | CP42: 2.04324 | CQ42: 2.04683 | CS42: 2.04732 | CT42: 2.05113 | CU42: 2.05113 | CV42: 2.05114 | CW42: 2.03969 | CX42: 2.03969 | CY42: 2.03718 | CZ42: 2.02328 | DA42: 2.02971 | DB42: 2.02971 | DC42: 1.93903
A43: =WEEKDAY(B43) -> 3 | B43: 42066 | D43: 0.57749 | E43: 0.57672 | F43: 0.6038 | G43: 0.60701 | H43: 0.6157 | I43: 0.53384 | J43: 0.60819 | K43: 0.55236 | L43: 0.57262 | M43: 0.58178 | N43: 0.50697 | O43: 0.64584 | P43: 0.6316 | Q43: 0.53509 | R43: 0.56688 | S43: 0.60862 | T43: 0.67077 | U43: 0.6155 | V43: 0.60502 | W43: 0.6823 | X43: 0.72118 | Y43: 0.83229 | Z43: 0.76385 | AA43: 0.83252 | AB43: 0.8326 | AC43: 0.92775 | AD43: 0.90381 | AE43: 0.82841 | AF43: 0.97579 | AG43: 1.0164 | AH43: 1.05997 | AI43: 1.06836 | AJ43: 1.06981 | AK43: 0.94343 | AL43: 1.14176 | AM43: 1.25971 | AN43: 1.07916 | AO43: 1.30709 | AP43: 1.38868 | AQ43: 1.21948 | AR43: 1.44038 | AS43: 1.48672 | AT43: 1.5263 | AU43: 1.52054 | AV43: 1.45268 | AW43: 1.90704 | AX43: 1.92336 | AY43: 1.95437 | AZ43: 1.96606 | BA43: 1.98299 | BB43: 2.0524 | BC43: 2.09134 | BD43: 2.11081 | BE43: 2.02204 | BF43: 2.17188 | BG43: 2.16689 | BH43: 2.16715 | BI43: 2.15592 | BJ43: 2.15593 | BK43: 2.16509 | BL43: 2.15086 | BM43: 2.1442 | BN43: 2.12986 | BO43: 2.09757 | BP43: 2.12489 | BQ43: 2.1249 | BR43: 2.12849 | BS43: 2.1285 | BT43: 2.12851 | BW43: 2.12354 | BX43: 2.12596 | BY43: 2.1189 | BZ43: 2.11164 | CA43: 2.11165 | CB43: 2.11165 | CC43: 2.11395 | CD43: 2.11395 | CE43: 2.10835 | CF43: 2.10835 | CG43: 2.10836 | CH43: 2.10836 | CI43: 2.10613 | CJ43: 2.09877 | CK43: 2.10171 | CL43: 2.10171 | CM43: 2.10172 | CN43: 2.10172 | CO43: 2.10379 | CP43: 2.10114 | CQ43: 2.09345 | CS43: 2.09373 | CT43: 2.08027 | CU43: 2.08027 | CV43: 2.08028 | CW43: 2.08128 | CX43: 2.08128 | CY43: 2.07878 | CZ43: 2.07379 | DA43: 2.07129 | DB43: 2.0713 | DC43: 1.98914
A44: =WEEKDAY(B44) -> 4 | B44: 42067 | D44: 0.55336 | E44: 0.62619 | F44: 0.64552 | G44: 0.68515 | H44: 0.66214 | I44: 0.61988 | J44: 0.67451 | K44: 0.64513 | L44: 0.66747 | M44: 0.69159 | N44: 0.62062 | O44: 0.74231 | P44: 0.73619 | Q44: 0.6546 | R44: 0.67944 | S44: 0.7432 | T44: 0.78315 | U44: 0.72082 | V44: 0.70674 | W44: 0.78333 | X44: 0.81272 | Y44: 0.93371 | Z44: 0.86199 | AA44: 0.93558 | AB44: 0.93458 | AC44: 1.0287 | AD44: 0.99024 | AE44: 0.92995 | AF44: 1.07517 | AG44: 1.10696 | AH44: 1.15602 | AI44: 1.14577 | AJ44: 1.1609 | AK44: 1.04121 | AL44: 1.23524 | AM44: 1.34214 | AN44: 1.15985 | AO44: 1.39187 | AP44: 1.47643 | AQ44: 1.30617 | AR44: 1.52274 | AS44: 1.56898 | AT44: 1.60378 | AU44: 1.59934 | AV44: 1.53095 | AW44: 1.98332 | AX44: 1.99884 | AY44: 2.03095 | AZ44: 2.04175 | BA44: 2.06275 | BB44: 2.12086 | BC44: 2.15561 | BD44: 2.18031 | BE44: 2.09442 | BF44: 2.23642 | BG44: 2.23144 | BH44: 2.23104 | BI44: 2.22149 | BJ44: 2.22151 | BK44: 2.23067 | BL44: 2.21155 | BM44: 2.2098 | BN44: 2.20156 | BO44: 2.16215 | BP44: 2.18926 | BQ44: 2.18927 | BR44: 2.21077 | BS44: 2.21079 | BT44: 2.2108 | BW44: 2.18919 | BX44: 2.19161 | BY44: 2.18363 | BZ44: 2.17606 | CA44: 2.17608 | CB44: 2.17609 | CC44: 2.18167 | CD44: 2.18168 | CE44: 2.17503 | CF44: 2.17504 | CG44: 2.17505 | CH44: 2.17154 | CI44: 2.1682 | CJ44: 2.16323 | CK44: 2.16618 | CL44: 2.16158 | CM44: 2.16159 | CN44: 2.16937 | CO44: 2.16454 | CP44: 2.16688 | CQ44: 2.15794 | CS44: 2.15946 | CT44: 2.14414 | CU44: 2.14415 | CV44: 2.14416 | CW44: 2.14702 | CX44: 2.14702 | CY44: 2.14453 | CZ44: 2.13954 | DA44: 2.13705 | DB44: 2.13705 | DC44: 2.05367
A45: =WEEKDAY(B45) -> 5 | B45: 42068 | D45: 0.46842 | E45: 0.61746 | F45: 0.64542 | G45: 0.65136 | H45: 0.67426 | I45: 0.62076 | J45: 0.68435 | K45: 0.65644 | L45: 0.6786 | M45: 0.70346 | N45: 0.63242 | O45: 0.75337 | P45: 0.74686 | Q45: 0.6686 | R45: 0.69212 | S45: 0.7565 | T45: 0.79692 | U45: 0.7411 | V45: 0.72777 | W45: 0.80335 | X45: 0.84185 | Y45: 0.95418 | Z45: 0.88048 | AA45: 0.95397 | AB45: 0.95299 | AC45: 1.02862 | AD45: 1.02123 | AE45: 0.94497 | AF45: 1.09158 | AG45: 1.11691 | AH45: 1.17707 | AI45: 1.1671 | AJ45: 1.18231 | AK45: 1.06222 | AL45: 1.25644 | AM45: 1.37086 | AN45: 1.19716 | AO45: 1.421 | AP45: 1.50038 | AQ45: 1.33644 | AR45: 1.54668 | AS45: 1.5875 | AT45: 1.62165 | AU45: 1.6155 | AV45: 1.54573 | AW45: 2.00802 | AX45: 2.02464 | AY45: 2.05234 | AZ45: 2.06762 | BA45: 2.08342 | BB45: 2.1477 | BC45: 2.19242 | BD45: 2.21076 | BE45: 2.11604 | BF45: 2.26248 | BG45: 2.2575 | BH45: 2.25736 | BI45: 2.24234 | BJ45: 2.24657 | BK45: 2.25666 | BL45: 2.23661 | BM45: 2.23579 | BN45: 2.22209 | BO45: 2.19071 | BP45: 2.21712 | BQ45: 2.21714 | BR45: 2.21381 | BS45: 2.21383 | BT45: 2.21384 | BW45: 2.21055 | BX45: 2.21426 | BY45: 2.21129 | BZ45: 2.20393 | CA45: 2.20394 | CB45: 2.20395 | CC45: 2.20635 | CD45: 2.20636 | CE45: 2.20065 | CF45: 2.20066 | CG45: 2.20067 | CH45: 2.19939 | CI45: 2.19698 | CJ45: 2.19386 | CK45: 2.19129 | CL45: 2.19129 | CM45: 2.1913 | CN45: 2.19407 | CO45: 2.19647 | CP45: 2.18908 | CQ45: 2.19447 | CS45: 2.18692 | CT45: 2.1794 | CU45: 2.17941 | CV45: 2.17941 | CW45: 2.16639 | CX45: 2.16639 | CY45: 2.1639 | CZ45: 2.16391 | DA45: 2.16497 | DB45: 2.16498 | DC45: 2.08087
A46: =WEEKDAY(B46) -> 6 | B46: 42069 | D46: 0.43822 | E46: 0.60936 | F46: 0.65503 | G46: 0.64952 | H46: 0.67746 | I46: 0.61276 | J46: 0.68925 | K46: 0.6603 | L46: 0.68252 | M46: 0.69057 | N46: 0.62865 | O46: 0.76774 | P46: 0.7589 | Q46: 0.67874 | R46: 0.68529 | S46: 0.73843 | T46: 0.80436 | U46: 0.75013 | V46: 0.73668 | W46: 0.81005 | X46: 0.85002 | Y46: 0.98884 | Z46: 0.92229 | AA46: 0.99657 | AB46: 0.9943 | AC46: 1.07742 | AD46: 1.07173 | AE46: 0.99856 | AF46: 1.14155 | AG46: 1.17448 | AH46: 1.23132 | AI46: 1.22955 | AJ46: 1.23883 | AK46: 1.11731 | AL46: 1.31228 | AM46: 1.43369 | AN46: 1.25151 | AO46: 1.48895 | AP46: 1.5825 | AQ46: 1.41688 | AR46: 1.62881 | AS46: 1.67234 | AT46: 1.70587 | AU46: 1.70258 | AV46: 1.63982 | AW46: 2.0987 | AX46: 2.11519 | AY46: 2.14621 | AZ46: 2.16401 | BA46: 2.17901 | BB46: 2.23559 | BC46: 2.27045 | BD46: 2.30735 | BE46: 2.21831 | BF46: 2.36305 | BG46: 2.35807 | BH46: 2.35785 | BI46: 2.34284 | BJ46: 2.34714 | BK46: 2.35792 | BL46: 2.33718 | BM46: 2.33628 | BN46: 2.32259 | BO46: 2.29358 | BP46: 2.31762 | BQ46: 2.31764 | BR46: 2.31431 | BS46: 2.31433 | BT46: 2.31434 | BW46: 2.31105 | BX46: 2.31809 | BY46: 2.31659 | BZ46: 2.30443 | CA46: 2.30445 | CB46: 2.30446 | CC46: 2.30764 | CD46: 2.30765 | CE46: 2.30334 | CF46: 2.30336 | CG46: 2.30337 | CH46: 2.29997 | CI46: 2.30005 | CJ46: 2.29422 | CK46: 2.29096 | CL46: 2.29097 | CM46: 2.29098 | CN46: 2.29099 | CO46: 2.29776 | CP46: 2.28351 | CQ46: 2.29545 | CS46: 2.27353 | CT46: 2.27354 | CU46: 2.27355 | CV46: 2.27356 | CW46: 2.26606 | CX46: 2.26607 | CY46: 2.26358 | CZ46: 2.26359 | DA46: 2.25609 | DB46: 2.2561
A47: =WEEKDAY(B47) -> 2 | B47: 42072 | D47: 0.51898 | E47: 0.6079 | F47: 0.66734 | G47: 0.66082 | H47: 0.67487 | I47: 0.60098 | J47: 0.69806 | K47: 0.64494 | L47: 0.6557 | M47: 0.67323 | N47: 0.6096 | O47: 0.73976 | P47: 0.71032 | Q47: 0.65756 | R47: 0.67137 | S47: 0.74208 | T47: 0.77629 | U47: 0.74722 | V47: 0.7124 | W47: 0.78589 | X47: 0.82501 | Y47: 0.95837 | Z47: 0.88949 | AA47: 0.96253 | AB47: 0.96158 | AC47: 1.05965 | AD47: 1.03704 | AE47: 0.96338 | AF47: 1.1064 | AG47: 1.1408 | AH47: 1.19759 | AI47: 1.19339 | AJ47: 1.19921 | AK47: 1.08062 | AL47: 1.27677 | AM47: 1.40193 | AN47: 1.21625 | AO47: 1.45697 | AP47: 1.55699 | AQ47: 1.38358 | AR47: 1.60103 | AS47: 1.64595 | AT47: 1.67769 | AU47: 1.67177 | AV47: 1.60991 | AW47: 2.08414 | AX47: 2.10167 | AY47: 2.12905 | AZ47: 2.14178 | BA47: 2.15841 | BB47: 2.21752 | BC47: 2.2564 | BD47: 2.29213 | BE47: 2.20375 | BF47: 2.35084 | BG47: 2.34585 | BH47: 2.34739 | BI47: 2.33488 | BJ47: 2.33489 | BK47: 2.3299 | BL47: 2.32492 | BM47: 2.31993 | BN47: 2.29995 | BO47: 2.281 | BP47: 2.29596 | BQ47: 2.29597 | BR47: 2.29098 | BS47: 2.29098 | BT47: 2.29099 | BW47: 2.30101 | BX47: 2.30101 | BY47: 2.29287 | BZ47: 2.28956 | CA47: 2.28956 | CB47: 2.28957 | CC47: 2.28958 | CD47: 2.28958 | CE47: 2.28626 | CF47: 2.28627 | CG47: 2.28627 | CH47: 2.28613 | CI47: 2.28633 | CJ47: 2.28113 | CK47: 2.27611 | CL47: 2.27612 | CM47: 2.27612 | CN47: 2.27964 | CO47: 2.27798 | CP47: 2.26864 | CQ47: 2.27298 | CS47: 2.27361 | CT47: 2.26599 | CU47: 2.26599 | CV47: 2.266 | CW47: 2.26316 | CX47: 2.26316 | CY47: 2.26066 | CZ47: 2.24869 | DA47: 2.25318 | DB47: 2.25318 | DC47: 2.17139
A48: =WEEKDAY(B48) -> 3 | B48: 42073 | D48: 0.46873 | E48: 0.59515 | F48: 0.67219 | G48: 0.62787 | H48: 0.65674 | I48: 0.60056 | J48: 0.68813 | K48: 0.6308 | L48: 0.64605 | M48: 0.65831 | N48: 0.59888 | O48: 0.72582 | P48: 0.69877 | Q48: 0.65041 | R48: 0.66864 | S48: 0.73414 | T48: 0.7696 | U48: 0.71665 | V48: 0.70479 | W48: 0.78013 | X48: 0.8191 | Y48: 0.93983 | Z48: 0.86476 | AA48: 0.93631 | AB48: 0.93641 | AC48: 1.01572 | AD48: 1.00829 | AE48: 0.9339 | AF48: 1.08002 | AG48: 1.11239 | AH48: 1.1683 | AI48: 1.16625 | AJ48: 1.17267 | AK48: 1.05488 | AL48: 1.24736 | AM48: 1.36991 | AN48: 1.18706 | AO48: 1.42517 | AP48: 1.52092 | AQ48: 1.34901 | AR48: 1.56496 | AS48: 1.60789 | AT48: 1.64041 | AU48: 1.63356 | AV48: 1.56638 | AW48: 2.04682 | AX48: 2.06486 | AY48: 2.08989 | AZ48: 2.09828 | BA48: 2.11997 | BB48: 2.17957 | BC48: 2.21651 | BD48: 2.25851 | BE48: 2.16405 | BF48: 2.31134 | BG48: 2.30635 | BH48: 2.30772 | BI48: 2.29538 | BJ48: 2.29539 | BK48: 2.2904 | BL48: 2.28542 | BM48: 2.28042 | BN48: 2.26139 | BO48: 2.2421 | BP48: 2.2574 | BQ48: 2.25741 | BR48: 2.25242 | BS48: 2.25243 | BT48: 2.25244 | BW48: 2.25715 | BX48: 2.26151 | BY48: 2.25383 | BZ48: 2.25051 | CA48: 2.25052 | CB48: 2.25053 | CC48: 2.25053 | CD48: 2.25054 | CE48: 2.24722 | CF48: 2.24722 | CG48: 2.24723 | CH48: 2.2466 | CI48: 2.24728 | CJ48: 2.24395 | CK48: 2.23755 | CL48: 2.23756 | CM48: 2.23756 | CN48: 2.23757 | CO48: 2.23507 | CP48: 2.23008 | CQ48: 2.23393 | CS48: 2.23411 | CT48: 2.23286 | CU48: 2.23287 | CV48: 2.23287 | CW48: 2.22565 | CX48: 2.22565 | CY48: 2.22314 | CZ48: 2.21013 | DA48: 2.21566 | DB48: 2.21567 | DC48: 2.13234
A49: =WEEKDAY(B49) -> 4 | B49: 42074 | D49: 0.45453 | E49: 0.5699 | F49: 0.6642 | G49: 0.67159 | H49: 0.65779 | I49: 0.59787 | J49: 0.67432 | K49: 0.62563 | L49: 0.63768 | M49: 0.64989 | N49: 0.59491 | O49: 0.73541 | P49: 0.69168 | Q49: 0.64586 | R49: 0.65885 | S49: 0.73044 | T49: 0.76656 | U49: 0.70942 | V49: 0.69724 | W49: 0.77282 | X49: 0.8103 | Y49: 0.88983 | Z49: 0.8348 | AA49: 0.90777 | AB49: 0.90722 | AC49: 0.98281 | AD49: 0.97353 | AE49: 0.90036 | AF49: 1.04431 | AG49: 1.07061 | AH49: 1.13422 | AI49: 1.13026 | AJ49: 1.1365 | AK49: 1.01781 | AL49: 1.21284 | AM49: 1.33367 | AN49: 1.15476 | AO49: 1.38282 | AP49: 1.47291 | AQ49: 1.30185 | AR49: 1.51699 | AS49: 1.56143 | AT49: 1.59317 | AU49: 1.58649 | AV49: 1.52122 | AW49: 2.00592 | AX49: 2.02368 | AY49: 2.05005 | AZ49: 2.05629 | BA49: 2.07798 | BB49: 2.13927 | BC49: 2.17472 | BD49: 2.21272 | BE49: 2.12224 | BF49: 2.27005 | BG49: 2.26866 | BH49: 2.26873 | BI49: 2.25471 | BJ49: 2.25702 | BK49: 2.25204 | BL49: 2.24707 | BM49: 2.24208 | BN49: 2.22211 | BO49: 2.20249 | BP49: 2.22482 | BQ49: 2.22483 | BR49: 2.21316 | BS49: 2.21317 | BT49: 2.21319 | BW49: 2.22321 | BX49: 2.22322 | BY49: 2.21493 | BZ49: 2.21162 | CA49: 2.21163 | CB49: 2.21165 | CC49: 2.21166 | CD49: 2.21167 | CE49: 2.20835 | CF49: 2.20836 | CG49: 2.20837 | CH49: 2.20838 | CI49: 2.20784 | CJ49: 2.20111 | CK49: 2.19837 | CL49: 2.19838 | CM49: 2.19839 | CN49: 2.20177 | CO49: 2.19591 | CP49: 2.19092 | CQ49: 2.19511 | CS49: 2.1959 | CT49: 2.19883 | CU49: 2.19884 | CV49: 2.19885 | CW49: 2.18652 | CX49: 2.18653 | CY49: 2.18402 | CZ49: 2.17099 | DA49: 2.17655 | DB49: 2.17655 | DC49: 2.09356
A50: =WEEKDAY(B50) -> 5 | B50: 42075 | D50: 0.07953 | E50: 0.55106 | F50: 0.63981 | G50: 0.65825 | H50: 0.64426 | I50: 0.58602 | J50: 0.66444 | K50: 0.60852 | L50: 0.62215 | M50: 0.63799 | N50: 0.5825 | O50: 0.71786 | P50: 0.67693 | Q50: 0.63749 | R50: 0.65476 | S50: 0.71962 | T50: 0.77 | U50: 0.69671 | V50: 0.68521 | W50: 0.7626 | X50: 0.80095 | Y50: 0.88035 | Z50: 0.82606 | AA50: 0.89949 | AB50: 0.89821 | AC50: 0.97996 | AD50: 0.94265 | AE50: 0.88639 | AF50: 1.03223 | AG50: 1.06192 | AH50: 1.12062 | AI50: 1.10039 | AJ50: 1.12332 | AK50: 1.00423 | AL50: 1.19927 | AM50: 1.32524 | AN50: 1.14808 | AO50: 1.37409 | AP50: 1.46739 | AQ50: 1.30369 | AR50: 1.51146 | AS50: 1.5548 | AT50: 1.58719 | AU50: 1.58331 | AV50: 1.51566 | AW50: 1.99794 | AX50: 2.01445 | AY50: 2.04183 | AZ50: 2.05082 | BA50: 2.07588 | BB50: 2.13008 | BC50: 2.1669 | BD50: 2.21016 | BE50: 2.10465 | BF50: 2.26102 | BG50: 2.25771 | BH50: 2.25807 | BI50: 2.24442 | BJ50: 2.24781 | BK50: 2.24283 | BL50: 2.23785 | BM50: 2.23749 | BN50: 2.2129 | BO50: 2.19035 | BP50: 2.21553 | BQ50: 2.21555 | BR50: 2.20394 | BS50: 2.20396 | BT50: 2.20397 | BW50: 2.214 | BX50: 2.21401 | BY50: 2.20565 | BZ50: 2.20234 | CA50: 2.20235 | CB50: 2.20236 | CC50: 2.20237 | CD50: 2.20238 | CE50: 2.19906 | CF50: 2.19907 | CG50: 2.19909 | CH50: 2.19909 | CI50: 2.19837 | CJ50: 2.19178 | CK50: 2.18916 | CL50: 2.18917 | CM50: 2.18918 | CN50: 2.18919 | CO50: 2.18669 | CP50: 2.1817 | CQ50: 2.18582 | CS50: 2.18669 | CT50: 2.1905 | CU50: 2.19051 | CV50: 2.19051 | CW50: 2.17874 | CX50: 2.17874 | CY50: 2.17624 | CZ50: 2.17127 | DA50: 2.16876 | DB50: 2.16877 | DC50: 2.08081
A51: =WEEKDAY(B51) -> 6 | B51: 42076 | D51: 0.1218 | E51: 0.53617 | F51: 0.62513 | G51: 0.64907 | H51: 0.63591 | I51: 0.56854 | J51: 0.66441 | K51: 0.59329 | L51: 0.60311 | M51: 0.62609 | N51: 0.56618 | O51: 0.68857 | P51: 0.66451 | Q51: 0.60943 | R51: 0.63409 | S51: 0.69844 | T51: 0.73458 | U51: 0.67659 | V51: 0.66763 | W51: 0.74238 | X51: 0.79588 | Y51: 0.86149 | Z51: 0.80976 | AA51: 0.8792 | AB51: 0.87721 | AC51: 0.96379 | AD51: 0.92228 | AE51: 0.87035 | AF51: 1.01894 | AG51: 1.05935 | AH51: 1.11369 | AI51: 1.09393 | AJ51: 1.12284 | AK51: 0.98938 | AL51: 1.19311 | AM51: 1.31995 | AN51: 1.13705 | AO51: 1.3673 | AP51: 1.46439 | AQ51: 1.29136 | AR51: 1.51345 | AS51: 1.55277 | AT51: 1.58043 | AU51: 1.57385 | AV51: 1.50268 | AW51: 1.99305 | AX51: 1.9789 | AY51: 2.03731 | AZ51: 2.04715 | BA51: 2.06844 | BB51: 2.12181 | BC51: 2.15216 | BD51: 2.19578 | BE51: 2.10389 | BF51: 2.25204 | BG51: 2.24873 | BH51: 2.24684 | BI51: 2.23545 | BJ51: 2.23668 | BK51: 2.2317 | BL51: 2.22672 | BM51: 2.22173 | BN51: 2.20456 | BO51: 2.18123 | BP51: 2.20655 | BQ51: 2.20657 | BR51: 2.19611 | BS51: 2.19613 | BT51: 2.19614 | BW51: 2.19998 | BX51: 2.20338 | BY51: 2.19667 | BZ51: 2.19336 | CA51: 2.19337 | CB51: 2.19338 | CC51: 2.1955 | CD51: 2.19551 | CE51: 2.19008 | CF51: 2.19009 | CG51: 2.1901 | CH51: 2.18787 | CI51: 2.18719 | CJ51: 2.18593 | CK51: 2.18132 | CL51: 2.18133 | CM51: 2.18134 | CN51: 2.18135 | CO51: 2.18561 | CP51: 2.17387 | CQ51: 2.17685 | CS51: 2.16389 | CT51: 2.17581 | CU51: 2.17582 | CV51: 2.17582 | CW51: 2.16853 | CX51: 2.16854 | CY51: 2.15394 | CZ51: 2.15394 | DA51: 2.15856 | DB51: 2.15857 | DC51: 2.06605
A52: =WEEKDAY(B52) -> 2 | B52: 42079 | E52: 0.54495 | F52: 0.61283 | G52: 0.60441 | H52: 0.6121 | I52: 0.54608 | J52: 0.62854 | K52: 0.57383 | L52: 0.58651 | M52: 0.60556 | N52: 0.55008 | O52: 0.66917 | P52: 0.64622 | Q52: 0.60609 | R52: 0.61345 | S52: 0.68897 | T52: 0.72472 | U52: 0.66377 | V52: 0.65332 | W52: 0.72734 | X52: 0.78263 | Y52: 0.83667 | Z52: 0.78545 | AA52: 0.85369 | AB52: 0.85312 | AC52: 0.93049 | AD52: 0.8999 | AE52: 0.84414 | AF52: 0.99599 | AG52: 1.03659 | AH52: 1.09056 | AI52: 1.06827 | AJ52: 1.09969 | AK52: 0.97473 | AL52: 1.17009 | AM52: 1.2949 | AN52: 1.09784 | AO52: 1.33906 | AP52: 1.43243 | AQ52: 1.25844 | AR52: 1.48664 | AS52: 1.52032 | AT52: 1.54779 | AU52: 1.51527 | AV52: 1.47024 | AW52: 1.95078 | AX52: 1.96704 | AY52: 1.99804 | AZ52: 2.00857 | BA52: 2.02983 | BB52: 2.0938 | BC52: 2.11795 | BD52: 2.16163 | BE52: 2.07509 | BF52: 2.21866 | BG52: 2.21534 | BH52: 2.21571 | BI52: 2.20203 | BJ52: 2.20537 | BK52: 2.20038 | BL52: 2.1954 | BM52: 2.19041 | BN52: 2.17042 | BO52: 2.14671 | BP52: 2.16644 | BQ52: 2.16644 | BR52: 2.17644 | BS52: 2.17645 | BT52: 2.17646 | BW52: 2.17148 | BX52: 2.17149 | BY52: 2.16249 | BZ52: 2.15918 | CA52: 2.15919 | CB52: 2.15919 | CC52: 2.1592 | CD52: 2.15921 | CE52: 2.15588 | CF52: 2.15589 | CG52: 2.15589 | CH52: 2.15493 | CI52: 2.15494 | CJ52: 2.15293 | CK52: 2.14658 | CL52: 2.14658 | CM52: 2.14659 | CN52: 2.14659 | CO52: 2.1441 | CP52: 2.1491 | CQ52: 2.13661 | CS52: 2.14409 | CT52: 2.15567 | CU52: 2.15567 | CV52: 2.15568 | CW52: 2.13765 | CX52: 2.13766 | CY52: 2.13515 | CZ52: 2.13017 | DA52: 2.12767 | DB52: 2.12767 | DC52: 2.03436
A53: =WEEKDAY(B53) -> 3 | B53: 42080 | E53: 0.54842 | F53: 0.61277 | G53: 0.58892 | H53: 0.61338 | I53: 0.55135 | J53: 0.62852 | K53: 0.58791 | L53: 0.58914 | M53: 0.61252 | N53: 0.55468 | O53: 0.67032 | P53: 0.6655 | Q53: 0.60166 | R53: 0.6265 | S53: 0.6918 | T53: 0.72838 | U53: 0.66988 | V53: 0.66014 | W53: 0.73487 | X53: 0.78865 | Y53: 0.8228 | Z53: 0.77182 | AA53: 0.84078 | AB53: 0.84008 | AC53: 0.91537 | AD53: 0.88537 | AE53: 0.8298 | AF53: 0.97905 | AG53: 1.0209 | AH53: 1.08922 | AI53: 1.08698 | AJ53: 1.08345 | AK53: 0.95707 | AL53: 1.15414 | AM53: 1.26032 | AN53: 1.08671 | AO53: 1.30591 | AP53: 1.39438 | AQ53: 1.2268 | AR53: 1.44919 | AS53: 1.48948 | AT53: 1.51688 | AU53: 1.5089 | AV53: 1.43612 | AW53: 1.91833 | AX53: 1.93479 | AY53: 1.96522 | AZ53: 1.97589 | BA53: 1.99715 | BB53: 2.06215 | BC53: 2.08774 | BD53: 2.13191 | BE53: 2.03389 | BF53: 2.18709 | BG53: 2.18377 | BH53: 2.18217 | BI53: 2.17013 | BJ53: 2.1732 | BK53: 2.16821 | BL53: 2.16322 | BM53: 2.16156 | BN53: 2.15323 | BO53: 2.11353 | BP53: 2.14019 | BQ53: 2.1402 | BR53: 2.14376 | BS53: 2.12878 | BT53: 2.12879 | BW53: 2.13881 | BX53: 2.13881 | BY53: 2.13025 | BZ53: 2.12694 | CA53: 2.12695 | CB53: 2.12695 | CC53: 2.12696 | CD53: 2.12697 | CE53: 2.12364 | CF53: 2.12365 | CG53: 2.12366 | CH53: 2.12366 | CI53: 2.12161 | CJ53: 2.1154 | CK53: 2.1139 | CL53: 2.11391 | CM53: 2.11391 | CN53: 2.11702 | CO53: 2.11142 | CP53: 2.10643 | CQ53: 2.11036 | CS53: 2.11141 | CT53: 2.11409 | CU53: 2.11409 | CV53: 2.11409 | CW53: 2.10203 | CX53: 2.10203 | CY53: 2.09953 | CZ53: 2.09455 | DA53: 2.09205 | DB53: 2.09205 | DC53: 1.99715
A54: =WEEKDAY(B54) -> 4 | B54: 42081 | E54: 0.52384 | F54: 0.60517 | G54: 0.62749 | H54: 0.6005 | I54: 0.52234 | J54: 0.62484 | K54: 0.58493 | L54: 0.55088 | M54: 0.56066 | N54: 0.50159 | O54: 0.65196 | P54: 0.64384 | Q54: 0.54782 | R54: 0.56735 | S54: 0.6426 | T54: 0.68033 | U54: 0.62121 | V54: 0.61113 | W54: 0.68315 | X54: 0.73862 | Y54: 0.74305 | Z54: 0.69507 | AA54: 0.76265 | AB54: 0.7565 | AC54: 0.83366 | AD54: 0.82103 | AE54: 0.74667 | AF54: 0.89796 | AG54: 0.93908 | AH54: 1.00664 | AI54: 0.97389 | AJ54: 1.00133 | AK54: 0.86489 | AL54: 1.07154 | AM54: 1.16609 | AN54: 0.97711 | AO54: 1.21537 | AP54: 1.30014 | AQ54: 1.13287 | AR54: 1.35597 | AS54: 1.39766 | AT54: 1.42515 | AU54: 1.41765 | AV54: 1.34851 | AW54: 1.83062 | AX54: 1.84551 | AY54: 1.87802 | AZ54: 1.88829 | BA54: 1.91381 | BB54: 1.98215 | BC54: 2.0125 | BD54: 2.05636 | BE54: 1.96776 | BF54: 2.11356 | BG54: 2.11025 | BH54: 2.11054 | BI54: 2.09663 | BJ54: 2.09998 | BK54: 2.095 | BL54: 2.09002 | BM54: 2.08896 | BN54: 2.06506 | BO54: 2.04002 | BP54: 2.06607 | BQ54: 2.06608 | BR54: 2.0551 | BS54: 2.07011 | BT54: 2.07012 | BW54: 2.06516 | BX54: 2.06517 | BY54: 2.05617 | BZ54: 2.05286 | CA54: 2.05287 | CB54: 2.05288 | CC54: 2.05523 | CD54: 2.05524 | CE54: 2.04958 | CF54: 2.04959 | CG54: 2.0496 | CH54: 2.04788 | CI54: 2.04788 | CJ54: 2.0459 | CK54: 2.04031 | CL54: 2.04032 | CM54: 2.04033 | CN54: 2.04033 | CO54: 2.03784 | CP54: 2.03285 | CQ54: 2.03634 | CS54: 2.03785 | CT54: 2.04827 | CU54: 2.04828 | CV54: 2.04828 | CW54: 2.03028 | CX54: 2.03029 | CY54: 2.02779 | CZ54: 2.02281 | DA54: 2.02031 | DB54: 2.02032 | DC54: 1.92785
A55: =WEEKDAY(B55) -> 5 | B55: 42082 | E55: 0.5101 | F55: 0.58566 | G55: 0.59347 | H55: 0.58975 | I55: 0.51776 | J55: 0.60511 | K55: 0.57528 | L55: 0.54056 | M55: 0.55173 | N55: 0.49471 | O55: 0.63888 | P55: 0.61179 | Q55: 0.54875 | R55: 0.56764 | S55: 0.63379 | T55: 0.6709 | U55: 0.61214 | V55: 0.60233 | W55: 0.67539 | X55: 0.73006 | Y55: 0.74566 | Z55: 0.69538 | AA55: 0.76401 | AB55: 0.76303 | AC55: 0.83462 | AD55: 0.81459 | AE55: 0.74674 | AF55: 0.89732 | AG55: 0.93644 | AH55: 1.00312 | AI55: 0.97071 | AJ55: 0.998 | AK55: 0.86408 | AL55: 1.06752 | AM55: 1.16018 | AN55: 0.98315 | AO55: 1.208 | AP55: 1.29075 | AQ55: 1.1252 | AR55: 1.34577 | AS55: 1.38927 | AT55: 1.41622 | AU55: 1.4104 | AV55: 1.33981 | AW55: 1.81843 | AX55: 1.83132 | AY55: 1.86553 | AZ55: 1.8766 | BA55: 1.89788 | BB55: 1.95479 | BC55: 1.99208 | BD55: 2.03749 | BE55: 1.93869 | BF55: 2.09178 | BG55: 2.09118 | BH55: 2.0912 | BI55: 2.07756 | BJ55: 2.07998 | BK55: 2.075 | BL55: 2.07002 | BM55: 2.06896 | BN55: 2.06004 | BO55: 2.01796 | BP55: 2.04732 | BQ55: 2.04734 | BR55: 2.036 | BS55: 2.03602 | BT55: 2.03603 | BW55: 2.04515 | BX55: 2.04517 | BY55: 2.03743 | BZ55: 2.03412 | CA55: 2.03413 | CB55: 2.03414 | CC55: 2.03415 | CD55: 2.03416 | CE55: 2.03084 | CF55: 2.03085 | CG55: 2.03086 | CH55: 2.03028 | CI55: 2.0298 | CJ55: 2.02457 | CK55: 2.0212 | CL55: 2.02121 | CM55: 2.02122 | CN55: 2.02425 | CO55: 2.01873 | CP55: 2.01374 | CQ55: 2.0176 | CS55: 2.00377 | CT55: 2.01121 | CU55: 2.01121 | CV55: 2.01122 | CW55: 2.00828 | CX55: 2.00828 | CY55: 2.00578 | CZ55: 1.99381 | DA55: 1.9983 | DB55: 1.99831 | DC55: 1.90371
A56: =WEEKDAY(B56) -> 6 | B56: 42083 | E56: 0.50117 | F56: 0.55646 | G56: 0.59047 | H56: 0.57676 | I56: 0.49425 | J56: 0.57551 | K56: 0.57721 | L56: 0.52316 | M56: 0.54875 | N56: 0.48187 | O56: 0.60594 | P56: 0.60606 | Q56: 0.51096 | R56: 0.54506 | S56: 0.60906 | T56: 0.64749 | U56: 0.57983 | V56: 0.58547 | W56: 0.65993 | X56: 0.71332 | Y56: 0.72976 | Z56: 0.67958 | AA56: 0.74869 | AB56: 0.74758 | AC56: 0.8179 | AD56: 0.78301 | AE56: 0.73071 | AF56: 0.87899 | AG56: 0.91823 | AH56: 0.98426 | AI56: 0.95399 | AJ56: 0.98034 | AK56: 0.85347 | AL56: 1.0502 | AM56: 1.14274 | AN56: 0.96506 | AO56: 1.19263 | AP56: 1.2797 | AQ56: 1.11246 | AR56: 1.32874 | AS56: 1.37308 | AT56: 1.39979 | AU56: 1.39279 | AV56: 1.3241 | AW56: 1.80283 | AX56: 1.81305 | AY56: 1.84928 | AZ56: 1.86752 | BA56: 1.88782 | BB56: 1.95136 | BC56: 1.9787 | BD56: 2.01969 | BE56: 1.92074 | BF56: 2.08264 | BG56: 2.07934 | BH56: 2.07478 | BI56: 2.07028 | BJ56: 2.07254 | BK56: 2.06923 | BL56: 2.06258 | BM56: 2.05594 | BN56: 2.05037 | BO56: 2.00283 | BP56: 2.04039 | BQ56: 2.04041 | BR56: 2.04042 | BS56: 2.04043 | BT56: 2.04045 | BW56: 2.03548 | BX56: 2.03607 | BY56: 2.03274 | BZ56: 2.02552 | CA56: 2.01896 | CB56: 2.01897 | CC56: 2.02105 | CD56: 2.02106 | CE56: 2.01567 | CF56: 2.01568 | CG56: 2.01569 | CH56: 2.0157 | CI56: 2.01305 | CJ56: 2.0062 | CK56: 2.00563 | CL56: 2.00564 | CM56: 2.00564 | CN56: 2.00908 | CO56: 2.01095 | CP56: 2.00408 | CQ56: 2.00591 | CS56: 2.00215 | CT56: 1.99426 | CU56: 1.99426 | CV56: 1.98821 | CW56: 1.99093 | CX56: 1.99093 | CY56: 1.98843 | CZ56: 1.97824 | DA56: 1.98095 | DB56: 1.98096 | DC56: 1.88567
A57: =WEEKDAY(B57) -> 2 | B57: 42086 | E57: 0.53042 | F57: 0.56426 | G57: 0.59431 | H57: 0.57834 | I57: 0.4967 | J57: 0.57985 | K57: 0.58092 | L57: 0.52429 | M57: 0.54884 | N57: 0.48244 | O57: 0.60879 | P57: 0.58934 | Q57: 0.51 | R57: 0.53599 | S57: 0.60909 | T57: 0.64696 | U57: 0.5797 | V57: 0.58475 | W57: 0.64739 | X57: 0.71114 | Y57: 0.72934 | Z57: 0.67912 | AA57: 0.74815 | AB57: 0.74752 | AC57: 0.81735 | AD57: 0.7838 | AE57: 0.73055 | AF57: 0.8784 | AG57: 0.9182 | AH57: 0.98517 | AI57: 0.95521 | AJ57: 0.98082 | AK57: 0.84409 | AL57: 1.05185 | AM57: 1.14707 | AN57: 0.97387 | AO57: 1.19592 | AP57: 1.28188 | AQ57: 1.11406 | AR57: 1.3309 | AS57: 1.37553 | AT57: 1.40192 | AU57: 1.39566 | AV57: 1.32469 | AW57: 1.8085 | AX57: 1.79235 | AY57: 1.85246 | AZ57: 1.86859 | BA57: 1.88996 | BB57: 1.95349 | BC57: 1.98441 | BD57: 2.02498 | BE57: 1.92988 | BF57: 2.0913 | BG57: 2.08799 | BH57: 2.08303 | BI57: 2.07861 | BJ57: 2.0805 | BK57: 2.07718 | BL57: 2.07052 | BM57: 2.06387 | BN57: 2.05866 | BO57: 2.00975 | BP57: 2.04867 | BQ57: 2.04868 | BR57: 2.04869 | BS57: 2.04869 | BT57: 2.0487 | BW57: 2.04372 | BX57: 2.04395 | BY57: 2.04062 | BZ57: 2.03375 | CA57: 2.02749 | CB57: 2.0275 | CC57: 2.03146 | CD57: 2.03147 | CE57: 2.02481 | CF57: 2.02482 | CG57: 2.02482 | CH57: 2.02149 | CI57: 2.0215 | CJ57: 2.01475 | CK57: 2.02003 | CL57: 2.02004 | CM57: 2.02004 | CN57: 2.02004 | CO57: 2.02005 | CP57: 2.01504 | CQ57: 2.02628 | CS57: 2.01002 | CT57: 2.00626 | CU57: 2.00627 | CV57: 2.00627 | CW57: 1.99628 | CX57: 1.99628 | CY57: 1.99628 | CZ57: 1.99131 | DA57: 1.99249 | DB57: 1.9925 | DC57: 1.89511
A58: =WEEKDAY(B58) -> 3 | B58: 42087 | E58: 0.5271 | F58: 0.56812 | G58: 0.59585 | H58: 0.56883 | I58: 0.50711 | J58: 0.57984 | K58: 0.58301 | L58: 0.53444 | M58: 0.54585 | N58: 0.48702 | O58: 0.62475 | P58: 0.61145 | Q58: 0.52757 | R58: 0.55462 | S58: 0.62049 | T58: 0.6591 | U58: 0.59066 | V58: 0.59587 | W58: 0.6695 | X58: 0.72308 | Y58: 0.73127 | Z58: 0.68248 | AA58: 0.75051 | AB58: 0.74962 | AC58: 0.81931 | AD58: 0.78475 | AE58: 0.73096 | AF58: 0.88077 | AG58: 0.91973 | AH58: 0.9867 | AI58: 0.98124 | AJ58: 0.98439 | AK58: 0.84481 | AL58: 1.05375 | AM58: 1.14571 | AN58: 0.96788 | AO58: 1.19557 | AP58: 1.26806 | AQ58: 1.10293 | AR58: 1.32338 | AS58: 1.36814 | AT58: 1.39475 | AU58: 1.38941 | AV58: 1.32017 | AW58: 1.79834 | AX58: 1.81075 | AY58: 1.84597 | AZ58: 1.86574 | BA58: 1.87847 | BB58: 1.94197 | BC58: 1.97508 | BD58: 2.02312 | BE58: 1.92277 | BF58: 2.0794 | BG58: 2.07609 | BH58: 2.07336 | BI58: 2.06643 | BJ58: 2.06971 | BK58: 2.06146 | BL58: 2.05974 | BM58: 2.05309 | BN58: 2.04649 | BO58: 1.99672 | BP58: 2.0365 | BQ58: 2.03651 | BR58: 2.03652 | BS58: 2.03652 | BT58: 2.03653 | BW58: 2.03155 | BX58: 2.03317 | BY58: 2.02656 | BZ58: 2.02157 | CA58: 2.01459 | CB58: 2.0146 | CC58: 2.01461 | CD58: 2.01461 | CE58: 2.01129 | CF58: 2.01129 | CG58: 2.01066 | CH58: 2.00926 | CI58: 2.00927 | CJ58: 2.00357 | CK58: 1.99664 | CL58: 2.00569 | CM58: 2.00569 | CN58: 1.99665 | CO58: 2.0057 | CP58: 1.98917 | CQ58: 2.00069 | CS58: 1.99567 | CT58: 2.01011 | CU58: 2.01012 | CV58: 2.01012 | CW58: 1.98604 | CX58: 1.98605 | CY58: 1.98709 | CZ58: 1.98012 | DA58: 1.98082 | DB58: 1.98083 | DC58: 1.88861
A59: =WEEKDAY(B59) -> 4 | B59: 42088 | E59: 0.52608 | F59: 0.56075 | G59: 0.60744 | H59: 0.597 | I59: 0.51767 | J59: 0.57637 | K59: 0.58721 | L59: 0.55782 | M59: 0.57841 | N59: 0.51811 | O59: 0.63046 | P59: 0.63141 | Q59: 0.55501 | R59: 0.58212 | S59: 0.64619 | T59: 0.68599 | U59: 0.61459 | V59: 0.61962 | W59: 0.69384 | X59: 0.74661 | Y59: 0.79612 | Z59: 0.71566 | AA59: 0.78607 | AB59: 0.78404 | AC59: 0.85957 | AD59: 0.82672 | AE59: 0.76331 | AF59: 0.90856 | AG59: 0.94811 | AH59: 1.01353 | AI59: 0.98295 | AJ59: 1.01104 | AK59: 0.88214 | AL59: 1.08067 | AM59: 1.16783 | AN59: 0.99461 | AO59: 1.22306 | AP59: 1.29948 | AQ59: 1.1402 | AR59: 1.34853 | AS59: 1.39583 | AT59: 1.42224 | AU59: 1.41683 | AV59: 1.34472 | AW59: 1.83279 | AX59: 1.81639 | AY59: 1.87723 | AZ59: 1.89702 | BA59: 1.92299 | BB59: 1.97773 | BC59: 2.02194 | BD59: 2.06284 | BE59: 1.97045 | BF59: 2.12044 | BG59: 2.11713 | BH59: 2.10989 | BI59: 2.10587 | BJ59: 2.10799 | BK59: 2.10468 | BL59: 2.09803 | BM59: 2.09139 | BN59: 2.08596 | BO59: 2.03679 | BP59: 2.07598 | BQ59: 2.07599 | BR59: 2.07601 | BS59: 2.07602 | BT59: 2.07603 | BW59: 2.07107 | BX59: 2.07152 | BY59: 2.06819 | BZ59: 2.06111 | CA59: 2.05509 | CB59: 2.0551 | CC59: 2.05951 | CD59: 2.05952 | CE59: 2.05287 | CF59: 2.05288 | CG59: 2.05289 | CH59: 2.04956 | CI59: 2.04957 | CJ59: 2.04282 | CK59: 2.04812 | CL59: 2.04813 | CM59: 2.04814 | CN59: 2.04815 | CO59: 2.04816 | CP59: 2.04315 | CQ59: 2.05437 | CS59: 2.03814 | CT59: 2.03437 | CU59: 2.03438 | CV59: 2.03439 | CW59: 2.02439 | CX59: 2.0244 | CY59: 2.02441 | CZ59: 2.01943 | DA59: 2.02028 | DB59: 2.02029 | DC59: 1.92507
A60: =WEEKDAY(B60) -> 5 | B60: 42089 | E60: 0.57038 | F60: 0.61875 | G60: 0.63505 | H60: 0.63514 | I60: 0.58463 | J60: 0.64434 | K60: 0.64487 | L60: 0.63443 | M60: 0.65566 | N60: 0.60185 | O60: 0.70506 | P60: 0.7013 | Q60: 0.6469 | R60: 0.67055 | S60: 0.73828 | T60: 0.80096 | U60: 0.70062 | V60: 0.70497 | W60: 0.78282 | X60: 0.81514 | Y60: 0.87549 | Z60: 0.82497 | AA60: 0.89518 | AB60: 0.89395 | AC60: 0.97128 | AD60: 0.94191 | AE60: 0.87249 | AF60: 1.02218 | AG60: 1.05727 | AH60: 1.12676 | AI60: 1.09372 | AJ60: 1.11545 | AK60: 0.98499 | AL60: 1.18898 | AM60: 1.27915 | AN60: 1.10814 | AO60: 1.33217 | AP60: 1.41028 | AQ60: 1.24419 | AR60: 1.45601 | AS60: 1.50345 | AT60: 1.53474 | AU60: 1.52322 | AV60: 1.45823 | AW60: 1.93446 | AX60: 1.91927 | AY60: 1.97541 | AZ60: 1.9898 | BA60: 2.01256 | BB60: 2.06978 | BC60: 2.0989 | BD60: 2.14497 | BE60: 2.04941 | BF60: 2.18956 | BG60: 2.18626 | BH60: 2.18238 | BI60: 2.1713 | BJ60: 2.17826 | BK60: 2.17004 | BL60: 2.1683 | BM60: 2.16166 | BN60: 2.1551 | BO60: 2.10498 | BP60: 2.14412 | BQ60: 2.14413 | BR60: 2.14414 | BS60: 2.14416 | BT60: 2.14417 | BW60: 2.1392 | BX60: 2.14113 | BY60: 2.13423 | BZ60: 2.12924 | CA60: 2.12289 | CB60: 2.1229 | CC60: 2.12291 | CD60: 2.12292 | CE60: 2.1196 | CF60: 2.11961 | CG60: 2.11931 | CH60: 2.1179 | CI60: 2.11791 | CJ60: 2.11458 | CK60: 2.11434 | CL60: 2.11435 | CM60: 2.11436 | CN60: 2.11437 | CO60: 2.11437 | CP60: 2.10937 | CQ60: 2.10938 | CS60: 2.10437 | CT60: 2.11883 | CU60: 2.11884 | CV60: 2.11885 | CW60: 2.09705 | CX60: 2.09705 | CY60: 2.09474 | CZ60: 2.08977 | DA60: 2.08954 | DB60: 2.08954 | DC60: 2.00101
A61: =WEEKDAY(B61) -> 6 | B61: 42090 | E61: 0.55513 | F61: 0.61862 | G61: 0.61915 | H61: 0.62939 | I61: 0.54147 | J61: 0.64431 | K61: 0.63505 | L61: 0.58729 | M61: 0.60018 | N61: 0.5439 | O61: 0.68101 | P61: 0.6401 | Q61: 0.58172 | R61: 0.61225 | S61: 0.67978 | T61: 0.71286 | U61: 0.64078 | V61: 0.64562 | W61: 0.72248 | X61: 0.76356 | Y61: 0.80857 | Z61: 0.75616 | AA61: 0.8277 | AB61: 0.82527 | AC61: 0.90024 | AD61: 0.87353 | AE61: 0.79268 | AF61: 0.95105 | AG61: 0.98102 | AH61: 1.05583 | AI61: 1.02438 | AJ61: 1.04511 | AK61: 0.91545 | AL61: 1.11805 | AM61: 1.21444 | AN61: 1.04056 | AO61: 1.26791 | AP61: 1.33955 | AQ61: 1.17506 | AR61: 1.39088 | AS61: 1.43896 | AT61: 1.47036 | AU61: 1.47151 | AV61: 1.38878 | AW61: 1.86847 | AX61: 1.87825 | AY61: 1.91212 | AZ61: 1.92654 | BA61: 1.94931 | BB61: 2.01218 | BC61: 2.03624 | BD61: 2.08194 | BE61: 1.98823 | BF61: 2.13541 | BG61: 2.1321 | BH61: 2.1268 | BI61: 2.1211 | BJ61: 2.12288 | BK61: 2.11957 | BL61: 2.11292 | BM61: 2.10628 | BN61: 2.10119 | BO61: 2.04742 | BP61: 2.09521 | BQ61: 2.09523 | BR61: 2.09524 | BS61: 2.09525 | BT61: 2.09527 | BW61: 2.09239 | BX61: 2.08908 | BY61: 2.08576 | BZ61: 2.08243 | CA61: 2.07535 | CB61: 2.07536 | CC61: 2.07581 | CD61: 2.07582 | CE61: 2.06593 | CF61: 2.06594 | CG61: 2.06546 | CH61: 2.06547 | CI61: 2.06079 | CJ61: 2.05588 | CK61: 2.05545 | CL61: 2.05546 | CM61: 2.05547 | CN61: 2.05548 | CO61: 2.05298 | CP61: 2.04799 | CQ61: 2.05219 | CS61: 2.05298 | CT61: 2.05626 | CU61: 2.05627 | CV61: 2.05627 | CW61: 2.04411 | CX61: 2.04412 | CY61: 2.04161 | CZ61: 2.02806 | DA61: 2.03414 | DB61: 2.03414 | DC61: 1.95224
A62: =WEEKDAY(B62) -> 2 | B62: 42093 | E62: 0.57173 | F62: 0.61182 | G62: 0.62279 | H62: 0.61836 | I62: 0.53331 | J62: 0.62831 | K62: 0.62814 | L62: 0.58167 | M62: 0.59752 | N62: 0.544 | O62: 0.66094 | P62: 0.63459 | Q62: 0.57454 | R62: 0.59798 | S62: 0.66299 | T62: 0.72796 | U62: 0.62484 | V62: 0.62843 | W62: 0.70336 | X62: 0.7412 | Y62: 0.8045 | Z62: 0.74973 | AA62: 0.8212 | AB62: 0.81942 | AC62: 0.9086 | AD62: 0.85597 | AE62: 0.7881 | AF62: 0.94648 | AG62: 0.98076 | AH62: 1.05116 | AI62: 1.04679 | AJ62: 1.03882 | AK62: 0.91962 | AL62: 1.11135 | AM62: 1.22126 | AN62: 1.04102 | AO62: 1.27119 | AP62: 1.35405 | AQ62: 1.18728 | AR62: 1.40032 | AS62: 1.44614 | AT62: 1.4778 | AU62: 1.47787 | AV62: 1.40197 | AW62: 1.87536 | AX62: 1.86356 | AY62: 1.91878 | AZ62: 1.94043 | BA62: 1.96159 | BB62: 2.01766 | BC62: 2.03975 | BD62: 2.08417 | BE62: 1.98362 | BF62: 2.13887 | BG62: 2.13556 | BH62: 2.12713 | BI62: 2.12428 | BJ62: 2.12521 | BK62: 2.12189 | BL62: 2.11523 | BM62: 2.10858 | BN62: 2.10858 | BO62: 2.04701 | BP62: 2.10126 | BQ62: 2.10127 | BR62: 2.09837 | BS62: 2.09838 | BT62: 2.09838 | BW62: 2.09464 | BX62: 2.09131 | BY62: 2.08799 | BZ62: 2.08466 | CA62: 2.07843 | CB62: 2.07844 | CC62: 2.07801 | CD62: 2.07802 | CE62: 2.06863 | CF62: 2.06864 | CG62: 2.06878 | CH62: 2.06878 | CI62: 2.06338 | CJ62: 2.05805 | CK62: 2.0585 | CL62: 2.0585 | CM62: 2.05851 | CN62: 2.06214 | CO62: 2.06442 | CP62: 2.05102 | CQ62: 2.05989 | CS62: 2.04103 | CT62: 2.0484 | CU62: 2.04841 | CV62: 2.04841 | CW62: 2.04541 | CX62: 2.04542 | CY62: 2.04291 | CZ62: 2.03106 | DA62: 2.03543 | DB62: 2.03543 | DC62: 1.94013
A63: =WEEKDAY(B63) -> 3 | B63: 42094 | E63: 0.551 | F63: 0.59949 | G63: 0.63228 | H63: 0.62241 | I63: 0.53754 | J63: 0.62259 | K63: 0.62987 | L63: 0.577 | M63: 0.59205 | N63: 0.53227 | O63: 0.67798 | P63: 0.63699 | Q63: 0.56244 | R63: 0.59436 | S63: 0.66413 | T63: 0.69717 | U63: 0.60825 | V63: 0.61163 | W63: 0.67481 | X63: 0.729 | Y63: 0.78252 | Z63: 0.72971 | AA63: 0.80172 | AB63: 0.79826 | AC63: 0.88129 | AD63: 0.84448 | AE63: 0.78521 | AF63: 0.93506 | AG63: 0.96704 | AH63: 1.04278 | AI63: 1.03856 | AJ63: 1.02947 | AK63: 0.90035 | AL63: 1.10291 | AM63: 1.21415 | AN63: 1.03531 | AO63: 1.26504 | AP63: 1.3453 | AQ63: 1.17411 | AR63: 1.39104 | AS63: 1.43813 | AT63: 1.47048 | AU63: 1.45829 | AV63: 1.38931 | AW63: 1.8731 | AX63: 1.88434 | AY63: 1.9167 | AZ63: 1.93387 | BA63: 1.9563 | BB63: 2.01153 | BC63: 2.03365 | BD63: 2.07271 | BE63: 1.97224 | BF63: 2.13238 | BG63: 2.12908 | BH63: 2.1238 | BI63: 2.11828 | BJ63: 2.12015 | BK63: 2.11684 | BL63: 2.1102 | BM63: 2.10356 | BN63: 2.0984 | BO63: 2.04295 | BP63: 2.09242 | BQ63: 2.09244 | BR63: 2.09246 | BS63: 2.09247 | BT63: 2.09249 | BW63: 2.0897 | BX63: 2.08638 | BY63: 2.08307 | BZ63: 2.07974 | CA63: 2.07259 | CB63: 2.0726 | CC63: 2.07312 | CD63: 2.07314 | CE63: 2.06351 | CF63: 2.06352 | CG63: 2.0632 | CH63: 2.06285 | CI63: 2.06022 | CJ63: 2.05321 | CK63: 2.05271 | CL63: 2.05272 | CM63: 2.05273 | CN63: 2.05274 | CO63: 2.05025 | CP63: 2.04526 | CQ63: 2.04959 | CS63: 2.05024 | CT63: 2.04877 | CU63: 2.04878 | CV63: 2.04878 | CW63: 2.0418 | CX63: 2.0418 | CY63: 2.0393 | CZ63: 2.02535 | DA63: 2.03183 | DB63: 2.03184 | DC63: 1.9374
... A90: =WEEKDAY(B90) -> 6 | B90: 42132 | E90: 0.55929 | F90: 0.68301 | G90: 0.7114 | H90: 0.74606 | I90: 0.75554 | J90: 0.71177 | K90: 0.77143 | L90: 0.75024 | M90: 0.76693 | N90: 0.69728 | O90: 0.83965 | P90: 0.80239 | Q90: 0.72567 | R90: 0.76403 | S90: 0.86277 | T90: 0.85933 | U90: 0.77446 | V90: 0.81099 | W90: 0.87682 | X90: 0.92164 | Y90: 1.03444 | Z90: 0.97929 | AA90: 1.03248 | AB90: 1.03204 | AC90: 1.15592 | AD90: 1.13844 | AE90: 1.06336 | AF90: 1.20924 | AG90: 1.25847 | AH90: 1.32424 | AI90: 1.32064 | AJ90: 1.33526 | AK90: 1.21195 | AL90: 1.41399 | AM90: 1.5473 | AN90: 1.36855 | AO90: 1.60568 | AP90: 1.68523 | AQ90: 1.51477 | AR90: 1.73266 | AS90: 1.77116 | AT90: 1.81759 | AU90: 1.77128 | AV90: 1.71461 | AW90: 2.19109 | AX90: 2.20051 | AY90: 2.23024 | AZ90: 2.24633 | BA90: 2.27033 | BB90: 2.30875 | BC90: 2.32829 | BD90: 2.36739 | BE90: 2.27544 | BF90: 2.46186 | BG90: 2.44658 | BH90: 2.44051 | BI90: 2.43223 | BJ90: 2.41874 | BK90: 2.43247 | BL90: 2.4126 | BM90: 2.41271 | BN90: 2.41753 | BO90: 2.35111 | BP90: 2.39704 | BQ90: 2.39706 | BR90: 2.39707 | BS90: 2.39709 | BT90: 2.39211 | BW90: 2.38714 | BX90: 2.38887 | BY90: 2.38217 | BZ90: 2.37458 | CA90: 2.37459 | CB90: 2.3746 | CC90: 2.37893 | CD90: 2.37895 | CE90: 2.37091 | CF90: 2.37092 | CG90: 2.37101 | CH90: 2.36509 | CI90: 2.36234 | CJ90: 2.36182 | CK90: 2.36035 | CL90: 2.36036 | CM90: 2.36037 | CN90: 2.36038 | CO90: 2.35789 | CP90: 2.3529 | CQ90: 2.35041 | CS90: 2.35487 | CT90: 2.35488 | CU90: 2.35489 | CV90: 2.35489 | CW90: 2.36454 | CX90: 2.36455 | CY90: 2.34989 | CZ90: 2.34594 | DA90: 2.34343 | DB90: 2.34344 | DC90: 2.25322
